2018-05-24 15:37:39,574 ERROR: Exception on /annotations [GET] 
Traceback (most recent call last):
  File "/home/ubuntu/.virtualenvs/mpcs/lib/python3.6/site-packages/flask/app.py", line 1982, in wsgi_app
    response = self.full_dispatch_request()
  File "/home/ubuntu/.virtualenvs/mpcs/lib/python3.6/site-packages/flask/app.py", line 1614, in full_dispatch_request
    rv = self.handle_user_exception(e)
  File "/home/ubuntu/.virtualenvs/mpcs/lib/python3.6/site-packages/flask/app.py", line 1517, in handle_user_exception
    reraise(exc_type, exc_value, tb)
  File "/home/ubuntu/.virtualenvs/mpcs/lib/python3.6/site-packages/flask/_compat.py", line 33, in reraise
    raise value
  File "/home/ubuntu/.virtualenvs/mpcs/lib/python3.6/site-packages/flask/app.py", line 1612, in full_dispatch_request
    rv = self.dispatch_request()
  File "/home/ubuntu/.virtualenvs/mpcs/lib/python3.6/site-packages/flask/app.py", line 1598, in dispatch_request
    return self.view_functions[rule.endpoint](**req.view_args)
  File "/home/ubuntu/gas/decorators.py", line 31, in decorated_function
    return fn(*args, **kwargs)
  File "/home/ubuntu/gas/views.py", line 168, in annotations_list
    return render_template('annotations.html', annotations=annotations)
  File "/home/ubuntu/.virtualenvs/mpcs/lib/python3.6/site-packages/flask/templating.py", line 134, in render_template
    context, ctx.app)
  File "/home/ubuntu/.virtualenvs/mpcs/lib/python3.6/site-packages/flask/templating.py", line 116, in _render
    rv = template.render(context)
  File "/home/ubuntu/.virtualenvs/mpcs/lib/python3.6/site-packages/jinja2/asyncsupport.py", line 76, in render
    return original_render(self, *args, **kwargs)
  File "/home/ubuntu/.virtualenvs/mpcs/lib/python3.6/site-packages/jinja2/environment.py", line 1008, in render
    return self.environment.handle_exception(exc_info, True)
  File "/home/ubuntu/.virtualenvs/mpcs/lib/python3.6/site-packages/jinja2/environment.py", line 780, in handle_exception
    reraise(exc_type, exc_value, tb)
  File "/home/ubuntu/.virtualenvs/mpcs/lib/python3.6/site-packages/jinja2/_compat.py", line 37, in reraise
    raise value.with_traceback(tb)
  File "/home/ubuntu/gas/templates/annotations.html", line 6, in top-level template code
    {% extends "base.html" %}
  File "/home/ubuntu/gas/templates/base.html", line 73, in top-level template code
    {% block body %}{% endblock %}
  File "/home/ubuntu/gas/templates/annotations.html", line 36, in block "body"
    <td><a href="{{ url_for('annotations_details', id=job.job_id) }}">{{ job.job_id }}</a></td>
  File "/home/ubuntu/.virtualenvs/mpcs/lib/python3.6/site-packages/flask/helpers.py", line 333, in url_for
    return appctx.app.handle_url_build_error(error, endpoint, values)
  File "/home/ubuntu/.virtualenvs/mpcs/lib/python3.6/site-packages/flask/app.py", line 1805, in handle_url_build_error
    reraise(exc_type, exc_value, tb)
  File "/home/ubuntu/.virtualenvs/mpcs/lib/python3.6/site-packages/flask/_compat.py", line 33, in reraise
    raise value
  File "/home/ubuntu/.virtualenvs/mpcs/lib/python3.6/site-packages/flask/helpers.py", line 323, in url_for
    force_external=external)
  File "/home/ubuntu/.virtualenvs/mpcs/lib/python3.6/site-packages/werkzeug/routing.py", line 1776, in build
    raise BuildError(endpoint, values, method, self)
werkzeug.routing.BuildError: Could not build url for endpoint 'annotations_details' with values ['id']. Did you mean 'annotation_details' instead?
